# 🛠️ Understanding `try...catch` in JavaScript

## 📌 Introduction
In JavaScript, errors can occur for various reasons—invalid inputs, incorrect API calls, or undefined values. To handle these errors gracefully, we use the `try...catch` statement. 

### 🔹 What is `try...catch`?
The `try...catch` block allows us to handle errors without stopping the execution of the entire program. If an error occurs in the `try` block, execution jumps to the `catch` block where we can manage the error appropriately.

---

## 🔍 Why Use `try...catch`?
✅ Prevents unexpected crashes 🚀  
✅ Provides meaningful error messages 📢  
✅ Improves debugging experience 🔍  
✅ Allows recovery from errors 💡  

---

## 📌 Syntax of `try...catch`
```javascript
try {
    // Code that may throw an error
} catch (error) {
    // Code to handle the error
}
```

The `try` block contains the code that might cause an error. If an error occurs, it is caught in the `catch` block.

---

## 📖 Example 1: Handling Undefined Properties
```javascript
const user = {
    name: 'Ritik',
    age: 24,
};

try {
    console.log(user.address.city); // ❌ Throws an error because 'address' is undefined
} catch (err) {
    console.dir(err.message); // Logs: Cannot read properties of undefined (reading 'city')
} finally {
    console.log('Hello World');
}

console.log(3 + 3);
```

### 🔍 Explanation:
1. `user.address.city` throws an error because `address` is undefined.
2. The `catch` block captures the error and logs it.
3. The `finally` block always executes, whether an error occurs or not.
4. The last `console.log(3 + 3)` still runs because `try...catch` prevents a crash.

---

## 📖 Example 2: Handling Errors in Async/Await
Handling errors in asynchronous code is essential because network requests might fail.

```javascript
async function makeSyncRequest() {
    try {
        const url = 'https://dummyjso.com/products?delay=2000'; // ❌ Wrong URL
        const response = await fetch(url);
        const data = await response.json();
        console.log(data);
        return data;
    } catch (err) {
        console.log(err); // Logs the error
        console.log('Something went wrong');
    }
}

makeSyncRequest();
```

### 🔍 Explanation:
1. We attempt to fetch data from an incorrect API (`dummyjso.com` instead of `dummyjson.com`).
2. The `fetch()` call fails, and the `catch` block captures the error.
3. The message `'Something went wrong'` is logged, allowing graceful error handling.

---

## 📌 The `finally` Block
The `finally` block executes **no matter what**—whether an error occurs or not.

```javascript
try {
    console.log('Trying to execute...');
    throw new Error('Oops! Something went wrong');
} catch (error) {
    console.log('Error caught:', error.message);
} finally {
    console.log('This runs no matter what');
}
```

### 🔍 Explanation:
1. An error is deliberately thrown inside `try`.
2. The `catch` block captures the error and logs the message.
3. The `finally` block runs regardless of whether an error was caught.

---

## ⚠️ Common Mistakes with `try...catch`
❌ Forgetting to use `catch` when handling async functions. Use `try...catch` or `.catch()` with promises.  
❌ Catching errors but not handling them properly. Always log or recover from errors.  
❌ Using `try...catch` unnecessarily—only wrap code that might fail.

---

## 🎯 Key Takeaways
✔ `try` contains the code that might throw an error.  
✔ `catch` handles the error and prevents crashes.  
✔ `finally` runs **no matter what**, even if an error occurs.  
✔ Essential for handling API failures and preventing unexpected crashes.

---

## 🎖️ Additional Resources
📌 [MDN Docs - try...catch](https://developer.mozilla.org/en-US/docs/Web/JavaScript/Reference/Statements/try...catch)  
📌 [JavaScript Error Handling](https://developer.mozilla.org/en-US/docs/Web/JavaScript/Reference/Global_Objects/Error)  

🚀 Keep coding and never fear errors—they're just part of learning! 😃

